<?xml version="1.0"?>
<sdf version="1.10">
  <model name="traffic_robot_red" canonical_link="base_link">
    <self_collide>false</self_collide>

    <!-- LiDAR mount frame, declared at model level (matches vehicle_blue convention). -->
    <frame name="lidar_frame" attached_to="base_link">
      <pose>0 0 0.20 0 0 0</pose>
    </frame>

    <!-- ====== CHASSIS (base_link) — sensors nested inside, matching vehicle_blue ====== -->
    <link name="base_link">
      <pose>0 0 0 0 0 0</pose>
      <inertial>
        <mass>5.0</mass>
        <inertia>
          <ixx>0.181667</ixx>
          <iyy>0.483333</iyy>
          <izz>0.566667</izz>
          <ixy>0</ixy><ixz>0</ixz><iyz>0</iyz>
        </inertia>
      </inertial>
      <visual name="visual">
        <geometry>
          <box><size>1.0 0.6 0.3</size></box>
        </geometry>
        <material>
          <ambient>0.6 0.0 0.0 1</ambient>
          <diffuse>0.85 0.05 0.05 1</diffuse>
          <specular>0.2 0.0 0.0 1</specular>
        </material>
      </visual>
      <collision name="collision">
        <geometry>
          <box><size>1.0 0.6 0.3</size></box>
        </geometry>
      </collision>

      <!-- ====== LIDAR (reduced spec per D-T5) — nested inside base_link to match vehicle_blue ====== -->
      <sensor name="gpu_lidar" type="gpu_lidar">
        <gz_frame_id>lidar_link</gz_frame_id>
        <pose relative_to="lidar_frame">0 0 0 0 0 0</pose>
        <update_rate>5</update_rate>
        <always_on>1</always_on>
        <visualize>false</visualize>
        <ray>
          <scan>
            <horizontal>
              <samples>45</samples>
              <resolution>1</resolution>
              <min_angle>-3.14159</min_angle>
              <max_angle>3.14159</max_angle>
            </horizontal>
            <vertical>
              <samples>1</samples>
              <resolution>1</resolution>
              <min_angle>0</min_angle>
              <max_angle>0</max_angle>
            </vertical>
          </scan>
          <range>
            <min>0.20</min>
            <max>5.0</max>
            <resolution>0.02</resolution>
          </range>
        </ray>
      </sensor>
    </link>

    <!-- ====== LEFT WHEEL ====== -->
    <link name="left_wheel">
      <pose relative_to="base_link">-0.25 0.30 -0.05 -1.5707963 0 0</pose>
      <inertial>
        <mass>0.5</mass>
        <inertia>
          <ixx>0.005625</ixx>
          <iyy>0.005625</iyy>
          <izz>0.010000</izz>
          <ixy>0</ixy><ixz>0</ixz><iyz>0</iyz>
        </inertia>
      </inertial>
      <visual name="visual">
        <geometry>
          <cylinder><radius>0.2</radius><length>0.1</length></cylinder>
        </geometry>
        <material>
          <ambient>0.05 0.05 0.05 1</ambient>
          <diffuse>0.1 0.1 0.1 1</diffuse>
        </material>
      </visual>
      <collision name="collision">
        <geometry>
          <cylinder><radius>0.2</radius><length>0.1</length></cylinder>
        </geometry>
        <surface>
          <friction>
            <ode><mu>1.0</mu><mu2>1.0</mu2></ode>
          </friction>
        </surface>
      </collision>
    </link>

    <!-- ====== RIGHT WHEEL ====== -->
    <link name="right_wheel">
      <pose relative_to="base_link">-0.25 -0.30 -0.05 -1.5707963 0 0</pose>
      <inertial>
        <mass>0.5</mass>
        <inertia>
          <ixx>0.005625</ixx>
          <iyy>0.005625</iyy>
          <izz>0.010000</izz>
          <ixy>0</ixy><ixz>0</ixz><iyz>0</iyz>
        </inertia>
      </inertial>
      <visual name="visual">
        <geometry>
          <cylinder><radius>0.2</radius><length>0.1</length></cylinder>
        </geometry>
        <material>
          <ambient>0.05 0.05 0.05 1</ambient>
          <diffuse>0.1 0.1 0.1 1</diffuse>
        </material>
      </visual>
      <collision name="collision">
        <geometry>
          <cylinder><radius>0.2</radius><length>0.1</length></cylinder>
        </geometry>
        <surface>
          <friction>
            <ode><mu>1.0</mu><mu2>1.0</mu2></ode>
          </friction>
        </surface>
      </collision>
    </link>

    <!-- ====== CASTER (front ball) ====== -->
    <link name="caster">
      <pose relative_to="base_link">0.40 0 -0.20 0 0 0</pose>
      <inertial>
        <mass>0.1</mass>
        <inertia>
          <ixx>0.0001</ixx>
          <iyy>0.0001</iyy>
          <izz>0.0001</izz>
          <ixy>0</ixy><ixz>0</ixz><iyz>0</iyz>
        </inertia>
      </inertial>
      <visual name="visual">
        <geometry>
          <sphere><radius>0.05</radius></sphere>
        </geometry>
        <material>
          <ambient>0.05 0.05 0.05 1</ambient>
          <diffuse>0.1 0.1 0.1 1</diffuse>
        </material>
      </visual>
      <collision name="collision">
        <geometry>
          <sphere><radius>0.05</radius></sphere>
        </geometry>
        <surface>
          <friction>
            <ode><mu>0.05</mu><mu2>0.05</mu2></ode>
          </friction>
        </surface>
      </collision>
    </link>

    <!-- ====== JOINTS ====== -->
    <joint name="left_wheel_joint" type="revolute">
      <parent>base_link</parent>
      <child>left_wheel</child>
      <axis>
        <xyz expressed_in="__model__">0 1 0</xyz>
        <limit>
          <lower>-1e16</lower>
          <upper>1e16</upper>
        </limit>
      </axis>
    </joint>

    <joint name="right_wheel_joint" type="revolute">
      <parent>base_link</parent>
      <child>right_wheel</child>
      <axis>
        <xyz expressed_in="__model__">0 1 0</xyz>
        <limit>
          <lower>-1e16</lower>
          <upper>1e16</upper>
        </limit>
      </axis>
    </joint>

    <joint name="caster_wheel" type="ball">
      <parent>base_link</parent>
      <child>caster</child>
    </joint>

    <!-- ====== DIFF-DRIVE PLUGIN ====== -->
    <plugin filename="gz-sim-diff-drive-system" name="gz::sim::systems::DiffDrive">
      <left_joint>left_wheel_joint</left_joint>
      <right_joint>right_wheel_joint</right_joint>
      <wheel_separation>0.6</wheel_separation>
      <wheel_radius>0.2</wheel_radius>
      <odom_publish_frequency>10.0</odom_publish_frequency>
      <frame_id>odom</frame_id>
      <child_frame_id>base_link</child_frame_id>
    </plugin>

  </model>
</sdf>
